[2023-05-06T07:47:29.039+0000] {taskinstance.py:1125} INFO - Dependencies all met for dep_context=non-requeueable deps ti=<TaskInstance: Raw_To_Processed_Job.Model_Training scheduled__2023-05-05T00:00:00+00:00 [queued]>
[2023-05-06T07:47:29.046+0000] {taskinstance.py:1125} INFO - Dependencies all met for dep_context=requeueable deps ti=<TaskInstance: Raw_To_Processed_Job.Model_Training scheduled__2023-05-05T00:00:00+00:00 [queued]>
[2023-05-06T07:47:29.047+0000] {taskinstance.py:1331} INFO - Starting attempt 1 of 1
[2023-05-06T07:47:29.064+0000] {taskinstance.py:1350} INFO - Executing <Task(PythonOperator): Model_Training> on 2023-05-05 00:00:00+00:00
[2023-05-06T07:47:29.071+0000] {standard_task_runner.py:57} INFO - Started process 15063 to run task
[2023-05-06T07:47:29.076+0000] {standard_task_runner.py:84} INFO - Running: ['airflow', 'tasks', 'run', 'Raw_To_Processed_Job', 'Model_Training', 'scheduled__2023-05-05T00:00:00+00:00', '--job-id', '149', '--raw', '--subdir', 'DAGS_FOLDER/DAG_Raw_to_processed.py', '--cfg-path', '/tmp/tmppmcfv5n3']
[2023-05-06T07:47:29.076+0000] {standard_task_runner.py:85} INFO - Job 149: Subtask Model_Training
[2023-05-06T07:47:29.127+0000] {task_command.py:410} INFO - Running <TaskInstance: Raw_To_Processed_Job.Model_Training scheduled__2023-05-05T00:00:00+00:00 [running]> on host sample-challenge.asia-south1-b.c.rt-de-sample-task.internal
[2023-05-06T07:47:29.191+0000] {taskinstance.py:1568} INFO - Exporting env vars: AIRFLOW_CTX_DAG_OWNER='airflow' AIRFLOW_CTX_DAG_ID='Raw_To_Processed_Job' AIRFLOW_CTX_TASK_ID='Model_Training' AIRFLOW_CTX_EXECUTION_DATE='2023-05-05T00:00:00+00:00' AIRFLOW_CTX_TRY_NUMBER='1' AIRFLOW_CTX_DAG_RUN_ID='scheduled__2023-05-05T00:00:00+00:00'
[2023-05-06T07:47:29.195+0000] {taskinstance.py:1847} ERROR - Task failed with exception
Traceback (most recent call last):
  File "/home/ebony_maw_0/.local/lib/python3.9/site-packages/airflow/operators/python.py", line 181, in execute
    return_value = self.execute_callable()
  File "/home/ebony_maw_0/.local/lib/python3.9/site-packages/airflow/operators/python.py", line 198, in execute_callable
    return self.python_callable(*self.op_args, **self.op_kwargs)
  File "/home/ebony_maw_0/code/Model_Training_function.py", line 11, in train_model
    data = pd.read_csv(r'/home/ebony_maw_0/data/model_training_data.csv/*.csv')
  File "/home/ebony_maw_0/.local/lib/python3.9/site-packages/pandas/io/parsers/readers.py", line 912, in read_csv
    return _read(filepath_or_buffer, kwds)
  File "/home/ebony_maw_0/.local/lib/python3.9/site-packages/pandas/io/parsers/readers.py", line 577, in _read
    parser = TextFileReader(filepath_or_buffer, **kwds)
  File "/home/ebony_maw_0/.local/lib/python3.9/site-packages/pandas/io/parsers/readers.py", line 1407, in __init__
    self._engine = self._make_engine(f, self.engine)
  File "/home/ebony_maw_0/.local/lib/python3.9/site-packages/pandas/io/parsers/readers.py", line 1661, in _make_engine
    self.handles = get_handle(
  File "/home/ebony_maw_0/.local/lib/python3.9/site-packages/pandas/io/common.py", line 859, in get_handle
    handle = open(
FileNotFoundError: [Errno 2] No such file or directory: '/home/ebony_maw_0/data/model_training_data.csv/*.csv'
[2023-05-06T07:47:29.200+0000] {taskinstance.py:1368} INFO - Marking task as FAILED. dag_id=Raw_To_Processed_Job, task_id=Model_Training, execution_date=20230505T000000, start_date=20230506T074729, end_date=20230506T074729
[2023-05-06T07:47:29.214+0000] {standard_task_runner.py:104} ERROR - Failed to execute job 149 for task Model_Training ([Errno 2] No such file or directory: '/home/ebony_maw_0/data/model_training_data.csv/*.csv'; 15063)
[2023-05-06T07:47:29.247+0000] {local_task_job_runner.py:232} INFO - Task exited with return code 1
[2023-05-06T07:47:29.261+0000] {taskinstance.py:2674} INFO - 0 downstream tasks scheduled from follow-on schedule check
